Workbook

Sheet Erläuterungen
A2: Zielsetzung
A4: F | B4: Schaffung einer zentralisierten Übersicht: Darstellung des Projektportfolios der Vorhaben der Leistungsvereinbarung, um eine einheitliche und transparente Sicht auf die Projektlandschaft zu ermöglichen.
A5: F | B5: Grundlage für Analysen und Berichte: Bereitstellung von Daten für Auswertungen und Berichte zum Projektportfolio.
A6: F | B6: Unterstützung der strategischen Steuerung: Ermöglichung einer effektiven Steuerung und Priorisierung der Projektlandschaft.
A7: F | B7: Förderung von Standards: Unterstützung der Anwendung anerkannter Projektmanagementmethoden und -standards.
A9: Hinweise und Disclaimer
A11: F | B11: Forschungs- und Drittmittelprojekte sind aufgrund ihrer spezifischen Anforderungen und der bestehenden Strukturen nicht in diesem Projektportfolio erfasst.
A12: F | B12: Hinweis zur Datenqualität: Die im Projektauftrag angeführten bzw. im Projektportfolio dargestellten Budget-, Kosten- oder Ressourcenzahlen sind mit Vorsicht zu interpretieren. Sie basieren auf Daten unterschiedlicher Qualität und aus verschiedenen Quellen (z.B. Budgetplanung, Maßnahmenplanung, Signing Memos, Sonderbudgets). Personalressourcen können derzeit weder in Stunden noch monetarisiert geschätzt werden. Ziel ist es, die Datenqualität und Aussagekraft der Angaben im Portfolio schrittweise zu verbessern.
A13: F | B13: Das primäre Ziel des vorliegenden Portfolios ist die Schaffung von Transparenz über die bestehende Projektlandschaft. In weiteren Ausbaustufen soll das Portfolio auf Projekte außerhalb der Leistungsvereinbarung ausgeweitet werden. Mit verbesserter Datenqualität soll es dazu beitragen, die strategische Ausrichtung der Projekte zu steuern, zu einer effizienten Ressourcenplanung und -nutzung beitragen und das Management von Projektrisiken unterstützen. So wird der Reifegrad des Portfolios schrittweise angehoben.
A16: Aufbau der Arbeitsblätter
C45: Information zum Lesen
C47: Berechnungsgrundlagen für Auswertungen
C49: Dateneingabe zu Projekten erforderlich
C51: Automatisierte Darstellung der Auswertungen
C53: Manuelle Auswertungen durch PPM erstellt

Sheet Parameter
B1: Parameter und Basisdaten für Dropdown Tabellen
B3: Gesetzliche Feiertage/Arbeitsfreie Tage | C3: Datum | E3: Projektauftrag | H3: Projektauftrag/PSB/Kooperationsprojekt/Budgeteinbehalt/LA | K3: LV-Vorhaben | M3: Projektklasse | P3: Projektphase | R3: in % | T3: Projektfortschritt | V3: Priorität | Y3: Risiko | AA3: PAG | AC3: Ampel | AE3: Innovationskraft | AH3: Leistungsbereich | AJ3: Kapitelzuordnung
B4: Neujahr | C4: 45658 | E4: Unterzeichnet | H4: Ja | I4: 1 | K4: LV25-27 | M4: Regelbetrieb | N4: 0 | P4: Idee erfasst/noch nicht gestartet | Q4: 1 | R4: 0 | T4: 0 | V4: Hoch | W4: 5 | Y4: Sehr Hoch | AA4: Rektor | AC4: In Ordnung | AE4: Hoch | AF4: 5 | AH4: A. Gesellschaftliche Zielsetzungen | AJ4: A. Allgemeine gesellschaftliche Zielsetzungen
B5: Heilige Drei Könige | C5: 45663 | E5: Entwurf | H5: n/a | K5: LV28-30 | M5: Projekt | N5: 1 | P5: Planung | Q5: 2 | R5: <10% | T5: 0.1 | V5: Mittel | W5: 3 | Y5: Hoch | AA5: VRLK | AC5: Vorsicht | AE5: Mittel | AF5: 3 | AH5: B. Forschung/Entwicklung | AJ5: A. Wissenschaftskommunikation/Wissenstransfer in die Gesellschaft
B6: Karfreitag | C6: 45765 | E6: Offen | H6: Nein | I6: 0 | K6: Nein | M6: Strategisches Projekt/Schlüsselprojekt/Programm | N6: 2 | P6: In Arbeit | Q6: 3 | R6: 10-99% | T6: 0.33 | V6: Gering | W6: 1 | Y6: Mittel | AA6: VRFDI | AC6: Krise | AE6: Gering | AF6: 1 | AH6: C. Lehre | AJ6: A. Qualitätssicherung
B7: Ostermontag | C7: 45768 | E7: n/a | P7: Blockiert | Q7: 4 | R7: - | T7: 0.25 | Y7: Gering | AA7: VRFIN | AH7: D. Sonstige | AJ7: A. Personalstruktur/-entwicklung
B8: Staatsfeiertag | C8: 45778 | P8: Abgeschlossen | Q8: 5 | R8: 1 | T8: 0.5 | Y8: Sehr Gering | AJ8: A. Standortwirkung
B9: Christi Himmelfahrt | C9: 45806 | P9: Abgebrochen | Q9: 6 | R9: - | T9: 0.66 | AJ9: B. Forschungsstärken
B10: Pfingstmontag | C10: 45817 | T10: 0.75 | AJ10: B. Großforschungsinfrastruktur
B11: Fronleichnam | C11: 45827 | T11: 0.9 | AJ11: B. Wissens-/Technologietransfer
B12: Mariä Himmelfahrt | C12: 45884 | T12: 1 | AJ12: B. Europäischer Forschungsraum
B13: Nationalfeiertag | C13: 45956 | T13: - | AJ13: C. Studienbereich
B14: Allerheiligen | C14: 45962 | AJ14: C. Qualitätssichernde Maßnahmen in der Lehre
B15: Mariä Empfängnis | C15: 45999 | AJ15: C. Lehr-/Lernorganisation
B16: Heiliger Abend | C16: 46015 | AJ16: C. Weiterbildung
B17: Christtag | C17: 46016 | AJ17: D. Kooperationen
B18: Stefanitag | C18: 46017 | AJ18: D. Bibliotheken
B19: Silvester | C19: 46022 | AJ19: D. Internationalisierung
B20: Neujahr | C20: 46023 | AJ20: D. Klinischer Bereich
B21: Heilige Drei Könige | C21: 46028 | AJ21: D. Forschungsinstitut für Wildtierkunde und Ökologie
B22: Karfreitag | C22: 46115
B23: Ostermontag | C23: 46118
B24: Staatsfeiertag | C24: 46143
B25: Christi Himmelfahrt | C25: 46156
B26: Pfingstmontag | C26: 46167
B27: Fronleichnam | C27: 46177
B28: Mariä Himmelfahrt | C28: 46249
B29: Nationalfeiertag | C29: 46321
B30: Allerheiligen | C30: 46327
B31: Mariä Empfängnis | C31: 46364
B32: Heiliger Abend | C32: 46380
B33: Christtag | C33: 46381
... B51: Silvester | C51: 46752

Sheet Arbeitsbereich
B1: Arbeitsbereich Auswertungen Dashboard | K1: Berichtsdatum: | M1: 46099
B3: Anzahl Projekte | D3: Gesamt | E3: in % | F3: Budgeteinbehalt | G3: in % | H3: Rektor | I3: in % | J3: VRLK | K3: in % | L3: VRFDI | M3: in % | N3: VRFIN | O3: in % | P3: A. Gesellschaftliche Zielsetzungen | Q3: in % | R3: B. Forschung/Entwicklung | S3: in % | T3: C. Lehre | U3: in % | V3: D. Sonstige | W3: in %
D4: =COUNTA(Tabelle1[Projektname/Bezeichnung des Vorhabens]) -> 4 | E4: =D4/D4 -> 1 | F4: =COUNTIF(Tabelle1[Budgeteinbehalt],"Ja") -> 1 | G4: =F4/$D$4 -> 0.25 | H4: =COUNTIF(Tabelle1[PAG],H3) -> 1 | I4: =H4/$D$4 -> 0.25 | J4: =COUNTIF(Tabelle1[PAG],J3) -> 2 | K4: =J4/$D$4 -> 0.5 | L4: =COUNTIF(Tabelle1[PAG],L3) -> 1 | M4: =L4/$D$4 -> 0.25 | N4: =COUNTIF(Tabelle1[PAG],N3) -> 0 | O4: =N4/$D$4 -> 0 | P4: =COUNTIF(Tabelle1[Leistungsbereich],P3) -> 1 | Q4: =P4/$D$4 -> 0.25 | R4: =COUNTIF(Tabelle1[Leistungsbereich],R3) -> 0 | S4: =R4/$D$4 -> 0 | T4: =COUNTIF(Tabelle1[Leistungsbereich],T3) -> 2 | U4: =T4/$D$4 -> 0.5 | V4: =COUNTIF(Tabelle1[Leistungsbereich],V3) -> 1 | W4: =V4/$D$4 -> 0.25
D5: =$D$4-D4 -> 0 | N5: =$D$4-H4 -> 3 | P5: =$D$4-J4 -> 2 | R5: =$D$4-L4 -> 3 | T5: =$D$4-N4 -> 4 | V5: =$D$4-P4 -> 3 | X5: =$D$4-R4 -> 4 | Z5: =$D$4-T4 -> 2 | AB5: =$D$4-V4 -> 3
B7: Anteil LV-Vorhaben | D7: Gesamt | E7: in % | F7: Rektor | G7: Rektor in % | H7: VRLK | I7: VRLK in % | J7: VRFDI | K7: VRFDI in % | L7: VRFIN | M7: VRFIN in %
C8: =Parameter!K4 -> LV25-27 | D8: =COUNTIF(Tabelle1[LV-Periode],Arbeitsbereich!C8) -> 4 | E8: =D8/$D$4 -> 1 | F8: =COUNTIFS(Tabelle1[LV-Periode],$C8,Tabelle1[PAG],$F$7) -> 1 | G8: =F8/$H$4 -> 1 | H8: =COUNTIFS(Tabelle1[LV-Periode],$C8,Tabelle1[PAG],$H$7) -> 2 | I8: =H8/$J$4 -> 1 | J8: =COUNTIFS(Tabelle1[LV-Periode],$C8,Tabelle1[PAG],$J$7) -> 1 | K8: =J8/$L$4 -> 1 | L8: =COUNTIFS(Tabelle1[LV-Periode],$C8,Tabelle1[PAG],$L$7) -> 0 | M8: =L8/$N$4 -> #DIV/0!
C9: =Parameter!K5 -> LV28-30 | D9: =COUNTIF(Tabelle1[LV-Periode],Arbeitsbereich!C9) -> 0 | E9: =D9/$D$4 -> 0 | F9: =COUNTIFS(Tabelle1[LV-Periode],$C9,Tabelle1[PAG],$F$7) -> 0 | G9: =F9/$H$4 -> 0 | H9: =COUNTIFS(Tabelle1[LV-Periode],$C9,Tabelle1[PAG],$H$7) -> 0 | I9: =H9/$J$4 -> 0 | J9: =COUNTIFS(Tabelle1[LV-Periode],$C9,Tabelle1[PAG],$J$7) -> 0 | K9: =J9/$L$4 -> 0 | L9: =COUNTIFS(Tabelle1[LV-Periode],$C9,Tabelle1[PAG],$L$7) -> 0 | M9: =L9/$N$4 -> #DIV/0!
C10: =Parameter!K6 -> Nein | D10: =COUNTIF(Tabelle1[LV-Periode],Arbeitsbereich!C10) -> 0 | E10: =D10/$D$4 -> 0 | F10: =COUNTIFS(Tabelle1[LV-Periode],$C10,Tabelle1[PAG],$F$7) -> 0 | G10: =F10/$H$4 -> 0 | H10: =COUNTIFS(Tabelle1[LV-Periode],$C10,Tabelle1[PAG],$H$7) -> 0 | I10: =H10/$J$4 -> 0 | J10: =COUNTIFS(Tabelle1[LV-Periode],$C10,Tabelle1[PAG],$J$7) -> 0 | K10: =J10/$L$4 -> 0 | L10: =COUNTIFS(Tabelle1[LV-Periode],$C10,Tabelle1[PAG],$L$7) -> 0 | M10: =L10/$N$4 -> #DIV/0!
C11: Keine Angabe | D11: =COUNTIF(Tabelle1[LV-Periode],"") -> 111 | E11: =D11/$D$4 -> 27.75 | F11: =COUNTIFS(Tabelle1[LV-Periode],"",Tabelle1[PAG],$F$7) -> 0 | G11: =F11/$H$4 -> 0 | H11: =COUNTIFS(Tabelle1[LV-Periode],"",Tabelle1[PAG],$H$7) -> 0 | I11: =H11/$J$4 -> 0 | J11: =COUNTIFS(Tabelle1[LV-Periode],"",Tabelle1[PAG],$J$7) -> 0 | K11: =J11/$L$4 -> 0 | L11: =COUNTIFS(Tabelle1[LV-Periode],"",Tabelle1[PAG],$L$7) -> 0 | M11: =L11/$N$4 -> #DIV/0!
B13: Projektauftrag | D13: Gesamt | E13: in % | F13: Budgeteinbehalt | G13: in % | H13: Summe Unterzeichnet + Entwurf Gesamt | I13: Summe Unterzeichnet + Entwurf Budgeteinbehalt
C14: Unterzeichnet | D14: =COUNTIF(Tabelle1[Projektauftrag],Arbeitsbereich!C14) -> 2 | E14: =D14/D4 -> 0.5 | F14: =COUNTIFS(Tabelle1[Projektauftrag],$C14,Tabelle1[Budgeteinbehalt],"ja") -> 0 | G14: =F14/$F$4 -> 0 | H14: =E14+E15 -> 0.75 | I14: =G14+G15 -> 0
C15: Entwurf | D15: =COUNTIF(Tabelle1[Projektauftrag],Arbeitsbereich!C15) -> 1 | E15: =D15/D4 -> 0.25 | F15: =COUNTIFS(Tabelle1[Projektauftrag],$C15,Tabelle1[Budgeteinbehalt],"ja") -> 0 | G15: =F15/$F$4 -> 0
C16: Offen | D16: =COUNTIF(Tabelle1[Projektauftrag],Arbeitsbereich!C16) -> 1 | E16: =D16/D4 -> 0.25 | F16: =COUNTIFS(Tabelle1[Projektauftrag],$C16,Tabelle1[Budgeteinbehalt],"ja") -> 1 | G16: =F16/$F$4 -> 1
C17: n/a | D17: =COUNTIF(Tabelle1[Projektauftrag],Arbeitsbereich!C17) -> 0 | E17: =D17/$D$4 -> 0 | F17: =COUNTIFS(Tabelle1[Projektauftrag],$C17,Tabelle1[Budgeteinbehalt],"ja") -> 0 | G17: =F17/$F$4 -> 0
B19: Berichtswesen (Abgabe PSB) | D19: Gesamt | E19: in % | F19: Budgeteinbehalt | G19: in %
C20: Ja | D20: =COUNTIF(Tabelle1[Projektstatusbericht (PSB)],Arbeitsbereich!C20) -> 4 | E20: =D20/$D$4 -> 1 | F20: =COUNTIFS(Tabelle1[Projektstatusbericht (PSB)],$C20,Tabelle1[Budgeteinbehalt],"ja") -> 1 | G20: =F20/$F$4 -> 1
B21: Achtung: Nein = Nein + n/a | C21: Nein | D21: =D4-D20 -> 0 | E21: =D21/$D$4 -> 0 | F21: =COUNTIFS(Tabelle1[Projektstatusbericht (PSB)],$C21,Tabelle1[Budgeteinbehalt],"ja") -> 0 | G21: =F21/$F$4 -> 0
B23: Anteil Lenkungsausschüsse | D23: Gesamt | E23: in % | F23: Budgeteinbehalt | G23: in %
C24: Ja | D24: =COUNTIF(Tabelle1[Lenkungs-ausschuss],Arbeitsbereich!C24) -> 1 | E24: =D24/$D$4 -> 0.25 | F24: =COUNTIFS(Tabelle1[Lenkungs-ausschuss],$C24,Tabelle1[Budgeteinbehalt],"ja") -> 0 | G24: =F24/$F$4 -> 0
C25: Nein | D25: =D4-D24 -> 3 | E25: =D25/$D$4 -> 0.75 | F25: =COUNTIFS(Tabelle1[Lenkungs-ausschuss],$C25,Tabelle1[Budgeteinbehalt],"ja") -> 0 | G25: =F25/$F$4 -> 0
B27: Anteil Kooperationsprojekte | D27: Gesamt | E27: in % | F27: Budgeteinbehalt | G27: in %
C28: Ja | D28: =COUNTIF(Tabelle1[Projekt mit externen Kooperationspartnern?],Arbeitsbereich!C28) -> 1 | E28: =D28/$D$4 -> 0.25 | F28: =COUNTIFS(Tabelle1[Projekt mit externen Kooperationspartnern?],$C28,Tabelle1[Budgeteinbehalt],"ja") -> 0 | G28: =F28/$F$4 -> 0
C29: Nein | D29: =D4-D28 -> 3 | E29: =D29/$D$4 -> 0.75 | F29: =COUNTIFS(Tabelle1[Projekt mit externen Kooperationspartnern?],$C29,Tabelle1[Budgeteinbehalt],"ja") -> 0 | G29: =F29/$F$4 -> 0
B31: Anteil Budgeteinbehalt | D31: Gesamt | E31: in %
C32: Ja | D32: =COUNTIF(Tabelle1[Budgeteinbehalt],Arbeitsbereich!C32) -> 1 | E32: =D32/$D$4 -> 0.25
C33: Nein | D33: =COUNTIF(Tabelle1[Budgeteinbehalt],Arbeitsbereich!C33) -> 0 | E33: =D33/$D$4 -> 0
B35: Leistungsbereich | D35: Gesamt | F35: Budgeteinbehalt | G35: in %
C36: A. Gesellschaftliche Zielsetzungen | D36: =IF(COUNTIF(Tabelle1[Leistungsbereich],Arbeitsbereich!C36)=0,NA(),COUNTIF(Tabelle1[Leistungsbereich],Arbeitsbereich!C36)) -> 1 | F36: =COUNTIFS(Tabelle1[Leistungsbereich],$C36,Tabelle1[Budgeteinbehalt],"ja") -> 0 | G36: =F36/$F$4 -> 0
C37: B. Forschung/Entwicklung | D37: =IF(COUNTIF(Tabelle1[Leistungsbereich],Arbeitsbereich!C37)=0,NA(),COUNTIF(Tabelle1[Leistungsbereich],Arbeitsbereich!C37)) -> #N/A | F37: =COUNTIFS(Tabelle1[Leistungsbereich],$C37,Tabelle1[Budgeteinbehalt],"ja") -> 0 | G37: =F37/$F$4 -> 0
C38: C. Lehre | D38: =IF(COUNTIF(Tabelle1[Leistungsbereich],Arbeitsbereich!C38)=0,NA(),COUNTIF(Tabelle1[Leistungsbereich],Arbeitsbereich!C38)) -> 2 | F38: =COUNTIFS(Tabelle1[Leistungsbereich],$C38,Tabelle1[Budgeteinbehalt],"ja") -> 1 | G38: =F38/$F$4 -> 1
C39: D. Sonstige | D39: =IF(COUNTIF(Tabelle1[Leistungsbereich],Arbeitsbereich!C39)=0,NA(),COUNTIF(Tabelle1[Leistungsbereich],Arbeitsbereich!C39)) -> 1 | F39: =COUNTIFS(Tabelle1[Leistungsbereich],$C39,Tabelle1[Budgeteinbehalt],"ja") -> 0 | G39: =F39/$F$4 -> 0
C40: Summe | D40: =SUM(D36:D39) -> #N/A
B42: Kapitelzuordnung | D42: Gesamt | F42: Budgeteinbehalt | G42: in %
B43: D. Sonstige | C43: Wildtierkunde und Ökologie | D43: =IF(COUNTIF(Tabelle1[Kapitelzuordnung],Arbeitsbereich!C43)=0,NA(),COUNTIF(Tabelle1[Kapitelzuordnung],Arbeitsbereich!C43)) -> #N/A | E43: =D43/$D$4 -> #N/A | F43: =COUNTIFS(Tabelle1[Kapitelzuordnung],C43,Tabelle1[Budgeteinbehalt],"ja") -> 0 | G43: =F43/$F$4 -> 0
B44: D. Sonstige | C44: Klinischer Bereich | D44: =IF(COUNTIF(Tabelle1[Kapitelzuordnung],Arbeitsbereich!C44)=0,NA(),COUNTIF(Tabelle1[Kapitelzuordnung],Arbeitsbereich!C44)) -> #N/A | E44: =D44/$D$4 -> #N/A | F44: =COUNTIFS(Tabelle1[Kapitelzuordnung],C44,Tabelle1[Budgeteinbehalt],"ja") -> 0 | G44: =F44/$F$4 -> 0
B45: D. Sonstige | C45: Internationalisierung | D45: =IF(COUNTIF(Tabelle1[Kapitelzuordnung],Arbeitsbereich!C45)=0,NA(),COUNTIF(Tabelle1[Kapitelzuordnung],Arbeitsbereich!C45)) -> #N/A | E45: =D45/$D$4 -> #N/A | F45: =COUNTIFS(Tabelle1[Kapitelzuordnung],C45,Tabelle1[Budgeteinbehalt],"ja") -> 0 | G45: =F45/$F$4 -> 0
B46: D. Sonstige | C46: Bibliothek | D46: =IF(COUNTIF(Tabelle1[Kapitelzuordnung],Arbeitsbereich!C46)=0,NA(),COUNTIF(Tabelle1[Kapitelzuordnung],Arbeitsbereich!C46)) -> #N/A | E46: =D46/$D$4 -> #N/A | F46: =COUNTIFS(Tabelle1[Kapitelzuordnung],C46,Tabelle1[Budgeteinbehalt],"ja") -> 0 | G46: =F46/$F$4 -> 0
B47: D. Sonstige | C47: Kooperationen | D47: =IF(COUNTIF(Tabelle1[Kapitelzuordnung],Arbeitsbereich!C47)=0,NA(),COUNTIF(Tabelle1[Kapitelzuordnung],Arbeitsbereich!C47)) -> 1 | E47: =D47/$D$4 -> 0.25 | F47: =COUNTIFS(Tabelle1[Kapitelzuordnung],C47,Tabelle1[Budgeteinbehalt],"ja") -> 0 | G47: =F47/$F$4 -> 0
B48: C. Lehre | C48: Weiterbildung | D48: =IF(COUNTIF(Tabelle1[Kapitelzuordnung],Arbeitsbereich!C48)=0,NA(),COUNTIF(Tabelle1[Kapitelzuordnung],Arbeitsbereich!C48)) -> 1 | E48: =D48/$D$4 -> 0.25 | F48: =COUNTIFS(Tabelle1[Kapitelzuordnung],C48,Tabelle1[Budgeteinbehalt],"ja") -> 1 | G48: =F48/$F$4 -> 1
B49: C. Lehre | C49: Lehr-/Lernorganisation | D49: =IF(COUNTIF(Tabelle1[Kapitelzuordnung],Arbeitsbereich!C49)=0,NA(),COUNTIF(Tabelle1[Kapitelzuordnung],Arbeitsbereich!C49)) -> #N/A | E49: =D49/$D$4 -> #N/A | F49: =COUNTIFS(Tabelle1[Kapitelzuordnung],C49,Tabelle1[Budgeteinbehalt],"ja") -> 0 | G49: =F49/$F$4 -> 0
...

Sheet Portfolio_Daten
E1: Projektportfolio Vorhaben der Leistungsvereinbarung | L1: Berichtsdatum: | M1: =Arbeitsbereich!M1 -> 46099
E3: Aktuelle LV-Periode: | F3: 2025-2027
B4: LV-Nummer | C4: Leistungsbereich | D4: Kapitelzuordnung | E4: Projektname/Bezeichnung des Vorhabens | F4: Kurzbeschreibung (Auslöser/Inhalte/Ziele) | G4: Relevante Meilensteine zur Umsetzung laut LV | H4: PL/ Ansprechperson | I4: PAG | J4: Beteiligte Organisationseinheit(en) | K4: LV-Periode | L4: Projektauftrag | M4: Projektstatusbericht (PSB) | N4: Lenkungs-ausschuss | O4: Projekt mit externen Kooperationspartnern? | P4: Thema für Begleitgespräch | Q4: Budgeteinbehalt | R4: Priorität | S4: Risiko | T4: Start | U4: Ende | V4: Dauer in Werktagen errechnet | W4: Kostenstelle/Innenauftrag | X4: Plankosten 2025 | Y4: Plankosten 2026 | Z4: Plankosten 2027 | AA4: Plankosten 25-27 | AB4: Istkosten 2025 | AC4: Istkosten 2026 | AD4: Istkosten 2027 | AE4: Ist-Kosten (Gesamt) | AF4: Ist-Kosten in% | AG4: Projektphase | AH4: Ampelstatus Gesamt | AI4: Fertigstellungs-grad (%) | AJ4: Dazugehörende Ziele | AK4: Status Zusammenfassung (Stand 01/26 - Wibi 25) | AL4: Risiken (Stand 01/26 - Wibi 25) | AM4: Entscheidungsbedarf (Stand 01/26 - Wibi 25) | AN4: Status Zusammenfassung (Stand 11/25)4 | AO4: Risiken (Stand 11/25)5 | AP4: Entscheidungsbedarf (Stand 11/25)6
B5: A1.1.1.1.1 | C5: A. Gesellschaftliche Zielsetzungen | D5: Vorhaben zur Qualitätssicherung | E5: Zentrale Beschaffung Labormaterialien | F5: Vollständige Digitalisierung und Standardisierung des Beschaffungsprozesses für Labormaterialien und Verbrauchsgüter | G5: 2026 Pilotbetrieb | I5: VRFDI | J5: Einkauf | K5: LV25-27 | L5: Unterzeichnet | M5: Ja | R5: Mittel | S5: Mittel | T5: 45689 | U5: 46568 | V5: =IF(U5="","",NETWORKDAYS(T5,U5,Parameter!$C$4:$C$51)) -> 596 | W5: LE1234567 | X5: 250000 | Y5: 100000 | Z5: 20000 | AA5: =SUM(Tabelle1[[#This Row],[Plankosten 2025]:[Plankosten 2027]]) -> 370000 | AB5: 10000 | AE5: =SUM(Tabelle1[[#This Row],[Istkosten 2025]:[Istkosten 2027]]) -> 10000 | AF5: =IF(AA5="","",Tabelle1[[#This Row],[Ist-Kosten (Gesamt)]]/Tabelle1[[#This Row],[Plankosten 25-27]]) -> 0.027027027 | AG5: In Arbeit | AH5: In Ordnung | AI5: 0.33 | AJ5: Nein | AK5: Ist-Prozesse wurden in 3 Workshops erfasst, derzeit werden Anforderungen an den Soll-Prozess und Mindestanforderungen erarbeitet, Umgang mit Sonderwünsche unklar, erst nach Klärung kann Entscheidung für Anbieter getroffen werden | AL5: Sonderwünsche bei Department A, Personelle Engpässe, es wird kein passendes Produkt gefunden, keine Direktvergabe möglich/Ausschreibung erforderlich | AM5: Umgang mit Sonderwünschen
B6: C1.2.2 | C6: C. Lehre | D6: Vorhaben zur Lehr-/Lernorganisation | E6: Digitale Lehr- und Prüfungsorganisation | F6: Digitale Lösungen sollen Abläufe in der zentralen Verwaltung transparent machen und vereinfachen. Im Bereich der Studienorganisation soll ein Tool zur zentralen Planung der Lehrorganisation (Stundenplan, Raumvergabe, Lehrveranstaltungs- und Prüfungsmanagement) eingeführt werden. | G6: 2026: Einführung Tool zur Lehrorganisation | I6: VRLK | J6: Lehrorganisation | K6: LV25-27 | L6: Unterzeichnet | M6: Ja | R6: Gering | S6: Gering | T6: 46023 | U6: 46752 | V6: =IF(U6="","",NETWORKDAYS(T6,U6,Parameter!$C$4:$C$51)) -> 497 | W6: - | X6: 0 | Y6: 0 | Z6: 0 | AA6: =SUM(Tabelle1[[#This Row],[Plankosten 2025]:[Plankosten 2027]]) -> 0 | AB6: 0 | AE6: =SUM(Tabelle1[[#This Row],[Istkosten 2025]:[Istkosten 2027]]) -> 0 | AF6: =IF(AA6="","",Tabelle1[[#This Row],[Ist-Kosten (Gesamt)]]/Tabelle1[[#This Row],[Plankosten 25-27]]) -> #DIV/0! | AG6: Planung | AH6: In Ordnung | AI6: 0 | AJ6: Ja | AK6: in Planung | AL6: keine
B7: C7.7.7.8 | C7: C. Lehre | D7: Weiterbildung | E7: Einführung Erweiterungsstudium Meereskrabben | F7: Bedarfsanalyse | G7: 2027: Bedarfsanalyse Erweiterungsstudium 4. BG | I7: VRLK | J7: Lehrorganisation | K7: LV25-27 | L7: Offen | M7: Ja | P7: Ja | Q7: Ja | R7: Gering | S7: Mittel | V7: =IF(U7="","",NETWORKDAYS(T7,U7,Parameter!$C$4:$C$51)) | W7: - | X7: 0 | Y7: 0 | Z7: 0 | AA7: =SUM(Tabelle1[[#This Row],[Plankosten 2025]:[Plankosten 2027]]) -> 0 | AB7: 0 | AE7: =SUM(Tabelle1[[#This Row],[Istkosten 2025]:[Istkosten 2027]]) -> 0 | AF7: =IF(AA7="","",Tabelle1[[#This Row],[Ist-Kosten (Gesamt)]]/Tabelle1[[#This Row],[Plankosten 25-27]]) -> #DIV/0! | AG7: Idee erfasst/noch nicht gestartet | AH7: Vorsicht | AI7: 0 | AJ7: Nein | AK7: ev. keine gesetzliche Deckung
B8: D3.3.3 | C8: D. Sonstige | D8: Kooperationen | E8: Neubau „Elefantenhaus“ – Trainings- und Untersuchungszentrum für Großsäuger | F8: Planung und Errichtung eines spezialisierten Trainings- und Untersuchungszentrums („Elefantenhaus“) zur praxisnahen Ausbildung, Forschung an schonenden Untersuchungsmethoden sowie zur vorübergehenden Betreuung von Großsäugern in Kooperation mit Partnereinrichtungen. Der Neubau umfasst zwei Innengehege mit Trainingsbereichen, zwei Außengehege, einen Untersuchungs- und Bildgebungsbereich, Quarantäneboxen, Futter- und Technikräume sowie Besucher- und Lehrflächen für Lehrveranstaltungen. Der Fokus liegt auf Tierwohl, Arbeitssicherheit, nachhaltiger Haustechnik und standardisierten Betriebsabläufen. | G8: 2025: Elefantenhaus konzeptionieren Ab 2027: Bau | I8: Rektor | J8: Campusmanagement | K8: LV25-27 | L8: Entwurf | M8: Ja | N8: Ja | O8: Ja | R8: Hoch | S8: Hoch | T8: 45658 | U8: 46752 | V8: =IF(U8="","",NETWORKDAYS(T8,U8,Parameter!$C$4:$C$51)) -> 744 | W8: LE9876543 | X8: 500000 | Y8: 1200000 | Z8: 13125 | AA8: =SUM(Tabelle1[[#This Row],[Plankosten 2025]:[Plankosten 2027]]) -> 1713125 | AB8: 0 | AE8: =SUM(Tabelle1[[#This Row],[Istkosten 2025]:[Istkosten 2027]]) -> 0 | AF8: =IF(AA8="","",Tabelle1[[#This Row],[Ist-Kosten (Gesamt)]]/Tabelle1[[#This Row],[Plankosten 25-27]]) -> 0 | AG8: Planung | AH8: Krise | AI8: 0.1 | AJ8: Nein | AK8: Abstimmungen BIG | AL8: Sicherstellung Finanzmittel mit Ministerium von Bauleitplan abhängig | AM8: Personelle Entscheidung zu treffen
V9: =IF(U9="","",NETWORKDAYS(T9,U9,Parameter!$C$4:$C$51)) | AA9: =SUM(Tabelle1[[#This Row],[Plankosten 2025]:[Plankosten 2027]]) -> 0 | AE9: =SUM(Tabelle1[[#This Row],[Istkosten 2025]:[Istkosten 2027]]) -> 0 | AF9: =IF(AA9="","",Tabelle1[[#This Row],[Ist-Kosten (Gesamt)]]/Tabelle1[[#This Row],[Plankosten 25-27]]) -> #DIV/0!
V10: =IF(U10="","",NETWORKDAYS(T10,U10,Parameter!$C$4:$C$51)) | AA10: =SUM(Tabelle1[[#This Row],[Plankosten 2025]:[Plankosten 2027]]) -> 0 | AE10: =SUM(Tabelle1[[#This Row],[Istkosten 2025]:[Istkosten 2027]]) -> 0 | AF10: =IF(AA10="","",Tabelle1[[#This Row],[Ist-Kosten (Gesamt)]]/Tabelle1[[#This Row],[Plankosten 25-27]]) -> #DIV/0!
V11: =IF(U11="","",NETWORKDAYS(T11,U11,Parameter!$C$4:$C$51)) | AA11: =SUM(Tabelle1[[#This Row],[Plankosten 2025]:[Plankosten 2027]]) -> 0 | AE11: =SUM(Tabelle1[[#This Row],[Istkosten 2025]:[Istkosten 2027]]) -> 0 | AF11: =IF(AA11="","",Tabelle1[[#This Row],[Ist-Kosten (Gesamt)]]/Tabelle1[[#This Row],[Plankosten 25-27]]) -> #DIV/0!
V12: =IF(U12="","",NETWORKDAYS(T12,U12,Parameter!$C$4:$C$51)) | AA12: =SUM(Tabelle1[[#This Row],[Plankosten 2025]:[Plankosten 2027]]) -> 0 | AE12: =SUM(Tabelle1[[#This Row],[Istkosten 2025]:[Istkosten 2027]]) -> 0 | AF12: =IF(AA12="","",Tabelle1[[#This Row],[Ist-Kosten (Gesamt)]]/Tabelle1[[#This Row],[Plankosten 25-27]]) -> #DIV/0!
V13: =IF(U13="","",NETWORKDAYS(T13,U13,Parameter!$C$4:$C$51)) | AA13: =SUM(Tabelle1[[#This Row],[Plankosten 2025]:[Plankosten 2027]]) -> 0 | AE13: =SUM(Tabelle1[[#This Row],[Istkosten 2025]:[Istkosten 2027]]) -> 0 | AF13: =IF(AA13="","",Tabelle1[[#This Row],[Ist-Kosten (Gesamt)]]/Tabelle1[[#This Row],[Plankosten 25-27]]) -> #DIV/0!
V14: =IF(U14="","",NETWORKDAYS(T14,U14,Parameter!$C$4:$C$51)) | AA14: =SUM(Tabelle1[[#This Row],[Plankosten 2025]:[Plankosten 2027]]) -> 0 | AE14: =SUM(Tabelle1[[#This Row],[Istkosten 2025]:[Istkosten 2027]]) -> 0 | AF14: =IF(AA14="","",Tabelle1[[#This Row],[Ist-Kosten (Gesamt)]]/Tabelle1[[#This Row],[Plankosten 25-27]]) -> #DIV/0!
V15: =IF(U15="","",NETWORKDAYS(T15,U15,Parameter!$C$4:$C$51)) | AA15: =SUM(Tabelle1[[#This Row],[Plankosten 2025]:[Plankosten 2027]]) -> 0 | AE15: =SUM(Tabelle1[[#This Row],[Istkosten 2025]:[Istkosten 2027]]) -> 0 | AF15: =IF(AA15="","",Tabelle1[[#This Row],[Ist-Kosten (Gesamt)]]/Tabelle1[[#This Row],[Plankosten 25-27]]) -> #DIV/0!
V16: =IF(U16="","",NETWORKDAYS(T16,U16,Parameter!$C$4:$C$51)) | AA16: =SUM(Tabelle1[[#This Row],[Plankosten 2025]:[Plankosten 2027]]) -> 0 | AE16: =SUM(Tabelle1[[#This Row],[Istkosten 2025]:[Istkosten 2027]]) -> 0 | AF16: =IF(AA16="","",Tabelle1[[#This Row],[Ist-Kosten (Gesamt)]]/Tabelle1[[#This Row],[Plankosten 25-27]]) -> #DIV/0!
V17: =IF(U17="","",NETWORKDAYS(T17,U17,Parameter!$C$4:$C$51)) | AA17: =SUM(Tabelle1[[#This Row],[Plankosten 2025]:[Plankosten 2027]]) -> 0 | AE17: =SUM(Tabelle1[[#This Row],[Istkosten 2025]:[Istkosten 2027]]) -> 0 | AF17: =IF(AA17="","",Tabelle1[[#This Row],[Ist-Kosten (Gesamt)]]/Tabelle1[[#This Row],[Plankosten 25-27]]) -> #DIV/0!
V18: =IF(U18="","",NETWORKDAYS(T18,U18,Parameter!$C$4:$C$51)) | AA18: =SUM(Tabelle1[[#This Row],[Plankosten 2025]:[Plankosten 2027]]) -> 0 | AE18: =SUM(Tabelle1[[#This Row],[Istkosten 2025]:[Istkosten 2027]]) -> 0 | AF18: =IF(AA18="","",Tabelle1[[#This Row],[Ist-Kosten (Gesamt)]]/Tabelle1[[#This Row],[Plankosten 25-27]]) -> #DIV/0!
V19: =IF(U19="","",NETWORKDAYS(T19,U19,Parameter!$C$4:$C$51)) | AA19: =SUM(Tabelle1[[#This Row],[Plankosten 2025]:[Plankosten 2027]]) -> 0 | AE19: =SUM(Tabelle1[[#This Row],[Istkosten 2025]:[Istkosten 2027]]) -> 0 | AF19: =IF(AA19="","",Tabelle1[[#This Row],[Ist-Kosten (Gesamt)]]/Tabelle1[[#This Row],[Plankosten 25-27]]) -> #DIV/0!
V20: =IF(U20="","",NETWORKDAYS(T20,U20,Parameter!$C$4:$C$51)) | AA20: =SUM(Tabelle1[[#This Row],[Plankosten 2025]:[Plankosten 2027]]) -> 0 | AE20: =SUM(Tabelle1[[#This Row],[Istkosten 2025]:[Istkosten 2027]]) -> 0 | AF20: =IF(AA20="","",Tabelle1[[#This Row],[Ist-Kosten (Gesamt)]]/Tabelle1[[#This Row],[Plankosten 25-27]]) -> #DIV/0!
... V119: =IF(U119="","",NETWORKDAYS(T119,U119,Parameter!$C$4:$C$51)) | AA119: =SUM(Tabelle1[[#This Row],[Plankosten 2025]:[Plankosten 2027]]) -> 0 | AE119: =SUM(Tabelle1[[#This Row],[Istkosten 2025]:[Istkosten 2027]]) -> 0 | AF119: =IF(AA119="","",Tabelle1[[#This Row],[Ist-Kosten (Gesamt)]]/Tabelle1[[#This Row],[Plankosten 25-27]]) -> #DIV/0!
B121: F | E121: Achtung: Zusätzliche Zeilen müssen innerhalb der bestehenden Tabelle eingefügt werden. Nur so bleiben die Formeln und Formatierungen erhalten! Zusätzliche Zeile und Formeln im Tabellenblatt "Zeitleiste" nachziehen.

Sheet Zielwerte
D1: Ziel(e) gemäß LV25-27 | E1: Indikator | F1: Ausgangswert 2023 | G1: Zielwert | J1: Referenz Vorhaben | K1: Istwert | P1: Anmerkungen 11/25 | Q1: Anmerkungen 02/26 (WIBI)
A2: Kapitel | B2: Leistungsbereich | C2: Nr. | G2: 2025 | H2: 2026 | I2: 2027 | K2: 2025 | L2: Abweichung absolut | M2: Abweichung in % | N2: 2026 | O2: 2027
A3: C1.2.2 | B3: Lehr-/Lernorganisation | C3: 1 | D3: Stärkung Digitalisierung | E3: Anzahl der abgearbeiteten Maßnahmen | F3: 1 | G3: 2 | H3: 2 | I3: 2 | J3: C1.2.2 | K3: 1 | L3: =K3-G3 -> -1 | M3: =IFERROR((K3-G3)/G3,"") -> -0.5 | P3: A2.2.1.1: 1 Maßnahme (zweisprachige Schilder) A2.2.1.2: 4 Maßnahmen (4 unterschiedliche Schulungen) A2.2.1.3: 1 Maßnahme (englische Ausgaben von vetmeduni inside) A2.2.1.4: 1 Maßnahme (Ausschreibung Stellen begünstigte Behinderte) | Q3: 2025 wurde eine Schulung für Mitarbeiter:innen der Verwaltung zu Stärkung der Digitalkompetenzen geplant, Durchführung 2026
L4: =K4-G4 -> 0 | M4: =IFERROR((K4-G4)/G4,"") | P4: Unter den OEAD Botschafter/innen-Profilen findet man aktuell 5 unter dem Stichwort „Vetmeduni“: Bieber, Burger, Burk, Pohlin, Schauberger und 3 weitere unter "Veterinärmedizinische": Dr. Oberließen (CF-WSC), Prof. Nowotny und Dr. Patzl. Zu prüfen, ob Prof. Nowotny und Dr. Patzl noch für Vetmeduni aktiv sind.
L5: =K5-G5 -> 0 | M5: =IFERROR((K5-G5)/G5,"") | P5: 4 VetmedTalks und 1 SDG-Vortrag werden bis 31.12.2025 umgesetzt
L6: =K6-G6 -> 0 | M6: =IFERROR((K6-G6)/G6,"") | P6: Bei "I wü wieda ham" waren am 23.10. OÖ, Stmk, Südtirol dabei
L7: =K7-G7 -> 0 | M7: =IFERROR((K7-G7)/G7,"") | N7: 4 | P7: 2 BIPA (Bioinformatik und Biostatistik; Labordiagnostik), 2 Klinisches Department für Nutztiere und Transformation von Lebensmittelsystemen ( Digitalisierung bei Nutztieren (Precision Livestock Farming (PLF) Hub); In vitro Darmmodelle)
L8: =K8-G8 -> 0 | M8: =IFERROR((K8-G8)/G8,"") | N8: 1 | P8: Teilnahme am Projekt wurde zugesagt. Die bisherigen Vorarbeiten durch das externe Projekt-Team sind im Zeitrahmen (Vorstellung der Lose Q4/2025-Q1/2026). Sobald die Lose bekannt sind muss sich die Universität für eine Vorgehensvariante (=Ausprägung) entscheiden. Evtl. müssen je nach Ausprägung noch Vorarbeiten geleistet werden.
L9: =K9-G9 -> 0 | M9: =IFERROR((K9-G9)/G9,"")
L10: =K10-G10 -> 0 | M10: =IFERROR((K10-G10)/G10,"") | P10: 1) Das Gründungstreffen hat am 7.10.2025 mit Departmentleiterinnen, Zentrumsleiterinnen und Stellvertreterinnen hat unter Beteilung des Rektorats stattgefunden._x000B_2) Das zweite Netzwerktreffen ist für 18.12.2025 mit einem gezielten Themenimpuls einer externen Referentin geplant.
L11: =K11-G11 -> 0 | M11: =IFERROR((K11-G11)/G11,"")
L12: =K12-G12 -> 0 | M12: =IFERROR((K12-G12)/G12,"") | P12: Entfristung mit 01.01.2025: Tatiana Marschik (Öff. Veterinärwesen und Epidemiologie) Das Dienstverhältnis endete durch Kündigung Dienstnehmerin per 30.09.2025. Künftige Entfristung mit 30.12.2025: Aldin Selimovic (FI für Wildtierkunde und Ökologie)
L13: =K13-G13 -> 0 | M13: =IFERROR((K13-G13)/G13,"") | P13: Vorhaben noch nicht begonnen (internes Doktoratsprogramm mit Laufzeit 1.1.2027 bis 30.6.2030)
L14: =K14-G14 -> 0 | M14: =IFERROR((K14-G14)/G14,"")
L15: =K15-G15 -> 0 | M15: =IFERROR((K15-G15)/G15,"")
L16: =K16-G16 -> 0 | M16: =IFERROR((K16-G16)/G16,"") | P16: Vorbereitung der Workshops 2026
L17: =K17-G17 -> 0 | M17: =IFERROR((K17-G17)/G17,"")
L18: =K18-G18 -> 0 | M18: =IFERROR((K18-G18)/G18,"") | P18: (Info 25.02.2026: im Excel war zuvor ein Ist-Wert von 9 angegeben)
L19: =K19-G19 -> 0 | M19: =IFERROR((K19-G19)/G19,"")

Sheet Zeitleiste
B1: Zeitleiste LV-Vorhaben | H1: Berichtsdatum: | I1: =Arbeitsbereich!M1 -> 46099
K3: =L5 -> 45670 | X3: =AH5 -> 45824 | AK3: =AL5 -> 45852 | AX3: =BH5 -> 46006 | BK3: =BL5 -> 46034 | BX3: =CH5 -> 46188 | CK3: =CL5 -> 46216 | CX3: =DH5 -> 46370 | DK3: =DL5 -> 46398 | DX3: =EH5 -> 46552 | EK3: =EL5 -> 46580 | EX3: =FH5 -> 46734 | FK3: =FL5 -> 46762
D4: Betrachtungszeitraum Start: | E4: 45658 | K4: =L5 -> 45670 | O4: =P5 -> 45698 | S4: =T5 -> 45726 | X4: =Y5 -> 45761 | AB4: =AC5 -> 45789 | AF4: =AG5 -> 45817 | AK4: =AL5 -> 45852 | AO4: =AP5 -> 45880 | AS4: =AT5 -> 45908 | AX4: =AY5 -> 45943 | BB4: =BC5 -> 45971 | BF4: =BG5 -> 45999 | BK4: =BL5 -> 46034 | BO4: =BP5 -> 46062 | BS4: =BT5 -> 46090 | BX4: =BY5 -> 46125 | CB4: =CC5 -> 46153 | CF4: =CG5 -> 46181 | CK4: =CL5 -> 46216 | CO4: =CP5 -> 46244 | CT4: =CU5 -> 46279 | CX4: =CY5 -> 46307 | DB4: =DC5 -> 46335 | DG4: =DH5 -> 46370 | DK4: =DL5 -> 46398 | DO4: =DP5 -> 46426 | DS4: =DT5 -> 46454 | DX4: =DY5 -> 46489 | EB4: =EC5 -> 46517 | EG4: =EH5 -> 46552 | EK4: =EL5 -> 46580 | EO4: =EP5 -> 46608 | ET4: =EU5 -> 46643 | EX4: =EY5 -> 46671 | FB4: =FC5 -> 46699 | FG4: =FH5 -> 46734 | FK4: =FL5 -> 46762 | FP4: =FQ5 -> 46797 | FT4: =FU5 -> 46825
D5: Aktuelles Datum: | E5: =TODAY() -> 46091 | G5: LV-Periode: | H5: 2025-2027 | J5: Wochenbeginn: | K5: =IF(MONTH(E4-WEEKDAY(E4,2)+1) < MONTH(E4), (E4-28-DAY(E4)+7) - WEEKDAY(E4-DAY(E4)+7,2)+1, (E4-DAY(E4)+7) - WEEKDAY(E4-DAY(E4)+7,2)+1) -> 45663 | L5: =K5+7 -> 45670 | M5: =L5+7 -> 45677 | N5: =M5+7 -> 45684 | O5: =N5+7 -> 45691 | P5: =O5+7 -> 45698 | Q5: =P5+7 -> 45705 | R5: =Q5+7 -> 45712 | S5: =R5+7 -> 45719 | ... FW5: =FV5+7 -> 46839
B6: ID | C6: LV-Nr. | D6: Kurzbezeichnung des Projekts | E6: Start | F6: Ende | G6: Dauer | H6: Projektphase | I6: Fortschritt (%)
B7: =Portfolio_Daten!#REF! -> #REF! | C7: =Portfolio_Daten!B5 -> A1.1.1.1.1 | D7: =Portfolio_Daten!E5 -> Zentrale Beschaffung Labormaterialien | E7: =Portfolio_Daten!T5 -> 45689 | F7: =Portfolio_Daten!U5 -> 46568 | G7: =IF(F7="","",NETWORKDAYS(E7,F7,Parameter!$C$4:$C$51)) -> 596 | H7: =Portfolio_Daten!AG5 -> In Arbeit | I7: =Portfolio_Daten!AI5 -> 0.33 | K7: =IF(K$5=($F7-WEEKDAY($F7,2)+1),"u","") | L7: =IF(L$5=($F7-WEEKDAY($F7,2)+1),"u","") | M7: =IF(M$5=($F7-WEEKDAY($F7,2)+1),"u","") | N7: =IF(N$5=($F7-WEEKDAY($F7,2)+1),"u","") | O7: =IF(O$5=($F7-WEEKDAY($F7,2)+1),"u","") | P7: =IF(P$5=($F7-WEEKDAY($F7,2)+1),"u","") | Q7: =IF(Q$5=($F7-WEEKDAY($F7,2)+1),"u","") | R7: =IF(R$5=($F7-WEEKDAY($F7,2)+1),"u","") | ... FW7: =IF(FW$5=($F7-WEEKDAY($F7,2)+1),"u","")
B8: =Portfolio_Daten!#REF! -> #REF! | C8: =Portfolio_Daten!B6 -> C1.2.2 | D8: =Portfolio_Daten!E6 -> Digitale Lehr- und Prüfungsorganisation | E8: =Portfolio_Daten!T6 -> 46023 | F8: =Portfolio_Daten!U6 -> 46752 | G8: =IF(F8="","",NETWORKDAYS(E8,F8,Parameter!$C$4:$C$51)) -> 497 | H8: =Portfolio_Daten!AG6 -> Planung | I8: =Portfolio_Daten!AI6 -> 0 | K8: =IF(K$5=($F8-WEEKDAY($F8,2)+1),"u","") | L8: =IF(L$5=($F8-WEEKDAY($F8,2)+1),"u","") | M8: =IF(M$5=($F8-WEEKDAY($F8,2)+1),"u","") | N8: =IF(N$5=($F8-WEEKDAY($F8,2)+1),"u","") | O8: =IF(O$5=($F8-WEEKDAY($F8,2)+1),"u","") | P8: =IF(P$5=($F8-WEEKDAY($F8,2)+1),"u","") | Q8: =IF(Q$5=($F8-WEEKDAY($F8,2)+1),"u","") | R8: =IF(R$5=($F8-WEEKDAY($F8,2)+1),"u","") | ... FW8: =IF(FW$5=($F8-WEEKDAY($F8,2)+1),"u","")
B9: =Portfolio_Daten!#REF! -> #REF! | C9: =Portfolio_Daten!B7 -> C7.7.7.8 | D9: =Portfolio_Daten!E7 -> Einführung Erweiterungsstudium Meereskrabben | E9: =Portfolio_Daten!T7 -> 0 | F9: =Portfolio_Daten!U7 -> 0 | G9: =IF(F9="","",NETWORKDAYS(E9,F9,Parameter!$C$4:$C$51)) -> 0 | H9: =Portfolio_Daten!AG7 -> Idee erfasst/noch nicht gestartet | I9: =Portfolio_Daten!AI7 -> 0 | K9: =IF(K$5=($F9-WEEKDAY($F9,2)+1),"u","") | L9: =IF(L$5=($F9-WEEKDAY($F9,2)+1),"u","") | M9: =IF(M$5=($F9-WEEKDAY($F9,2)+1),"u","") | N9: =IF(N$5=($F9-WEEKDAY($F9,2)+1),"u","") | O9: =IF(O$5=($F9-WEEKDAY($F9,2)+1),"u","") | P9: =IF(P$5=($F9-WEEKDAY($F9,2)+1),"u","") | Q9: =IF(Q$5=($F9-WEEKDAY($F9,2)+1),"u","") | R9: =IF(R$5=($F9-WEEKDAY($F9,2)+1),"u","") | ... FW9: =IF(FW$5=($F9-WEEKDAY($F9,2)+1),"u","")
B10: =Portfolio_Daten!#REF! -> #REF! | C10: =Portfolio_Daten!B8 -> D3.3.3 | D10: =Portfolio_Daten!E8 -> Neubau „Elefantenhaus“ – Trainings- und Untersuchungszentrum für Großsäuger | E10: =Portfolio_Daten!T8 -> 45658 | F10: =Portfolio_Daten!U8 -> 46752 | G10: =IF(F10="","",NETWORKDAYS(E10,F10,Parameter!$C$4:$C$51)) -> 744 | H10: =Portfolio_Daten!AG8 -> Planung | I10: =Portfolio_Daten!AI8 -> 0.1 | K10: =IF(K$5=($F10-WEEKDAY($F10,2)+1),"u","") | L10: =IF(L$5=($F10-WEEKDAY($F10,2)+1),"u","") | M10: =IF(M$5=($F10-WEEKDAY($F10,2)+1),"u","") | N10: =IF(N$5=($F10-WEEKDAY($F10,2)+1),"u","") | O10: =IF(O$5=($F10-WEEKDAY($F10,2)+1),"u","") | P10: =IF(P$5=($F10-WEEKDAY($F10,2)+1),"u","") | Q10: =IF(Q$5=($F10-WEEKDAY($F10,2)+1),"u","") | R10: =IF(R$5=($F10-WEEKDAY($F10,2)+1),"u","") | ... FW10: =IF(FW$5=($F10-WEEKDAY($F10,2)+1),"u","")
B11: =Portfolio_Daten!#REF! -> #REF! | C11: =Portfolio_Daten!B9 -> 0 | D11: =Portfolio_Daten!E9 -> 0 | E11: =Portfolio_Daten!T9 -> 0 | F11: =Portfolio_Daten!U9 -> 0 | G11: =IF(F11="","",NETWORKDAYS(E11,F11,Parameter!$C$4:$C$51)) -> 0 | H11: =Portfolio_Daten!AG9 -> 0 | I11: =Portfolio_Daten!AI9 -> 0 | K11: =IF(K$5=($F11-WEEKDAY($F11,2)+1),"u","") | L11: =IF(L$5=($F11-WEEKDAY($F11,2)+1),"u","") | M11: =IF(M$5=($F11-WEEKDAY($F11,2)+1),"u","") | N11: =IF(N$5=($F11-WEEKDAY($F11,2)+1),"u","") | O11: =IF(O$5=($F11-WEEKDAY($F11,2)+1),"u","") | P11: =IF(P$5=($F11-WEEKDAY($F11,2)+1),"u","") | Q11: =IF(Q$5=($F11-WEEKDAY($F11,2)+1),"u","") | R11: =IF(R$5=($F11-WEEKDAY($F11,2)+1),"u","") | ... FW11: =IF(FW$5=($F11-WEEKDAY($F11,2)+1),"u","")
B12: =Portfolio_Daten!#REF! -> #REF! | C12: =Portfolio_Daten!B10 -> 0 | D12: =Portfolio_Daten!E10 -> 0 | E12: =Portfolio_Daten!T10 -> 0 | F12: =Portfolio_Daten!U10 -> 0 | G12: =IF(F12="","",NETWORKDAYS(E12,F12,Parameter!$C$4:$C$51)) -> 0 | H12: =Portfolio_Daten!AG10 -> 0 | I12: =Portfolio_Daten!AI10 -> 0 | K12: =IF(K$5=($F12-WEEKDAY($F12,2)+1),"u","") | L12: =IF(L$5=($F12-WEEKDAY($F12,2)+1),"u","") | M12: =IF(M$5=($F12-WEEKDAY($F12,2)+1),"u","") | N12: =IF(N$5=($F12-WEEKDAY($F12,2)+1),"u","") | O12: =IF(O$5=($F12-WEEKDAY($F12,2)+1),"u","") | P12: =IF(P$5=($F12-WEEKDAY($F12,2)+1),"u","") | Q12: =IF(Q$5=($F12-WEEKDAY($F12,2)+1),"u","") | R12: =IF(R$5=($F12-WEEKDAY($F12,2)+1),"u","") | ... FW12: =IF(FW$5=($F12-WEEKDAY($F12,2)+1),"u","")
B13: =Portfolio_Daten!#REF! -> #REF! | C13: =Portfolio_Daten!B11 -> 0 | D13: =Portfolio_Daten!E11 -> 0 | E13: =Portfolio_Daten!T11 -> 0 | F13: =Portfolio_Daten!U11 -> 0 | G13: =IF(F13="","",NETWORKDAYS(E13,F13,Parameter!$C$4:$C$51)) -> 0 | H13: =Portfolio_Daten!AG11 -> 0 | I13: =Portfolio_Daten!AI11 -> 0 | K13: =IF(K$5=($F13-WEEKDAY($F13,2)+1),"u","") | L13: =IF(L$5=($F13-WEEKDAY($F13,2)+1),"u","") | M13: =IF(M$5=($F13-WEEKDAY($F13,2)+1),"u","") | N13: =IF(N$5=($F13-WEEKDAY($F13,2)+1),"u","") | O13: =IF(O$5=($F13-WEEKDAY($F13,2)+1),"u","") | P13: =IF(P$5=($F13-WEEKDAY($F13,2)+1),"u","") | Q13: =IF(Q$5=($F13-WEEKDAY($F13,2)+1),"u","") | R13: =IF(R$5=($F13-WEEKDAY($F13,2)+1),"u","") | ... FW13: =IF(FW$5=($F13-WEEKDAY($F13,2)+1),"u","")
B14: =Portfolio_Daten!#REF! -> #REF! | C14: =Portfolio_Daten!B12 -> 0 | D14: =Portfolio_Daten!E12 -> 0 | E14: =Portfolio_Daten!T12 -> 0 | F14: =Portfolio_Daten!U12 -> 0 | G14: =IF(F14="","",NETWORKDAYS(E14,F14,Parameter!$C$4:$C$51)) -> 0 | H14: =Portfolio_Daten!AG12 -> 0 | I14: =Portfolio_Daten!AI12 -> 0 | K14: =IF(K$5=($F14-WEEKDAY($F14,2)+1),"u","") | L14: =IF(L$5=($F14-WEEKDAY($F14,2)+1),"u","") | M14: =IF(M$5=($F14-WEEKDAY($F14,2)+1),"u","") | N14: =IF(N$5=($F14-WEEKDAY($F14,2)+1),"u","") | O14: =IF(O$5=($F14-WEEKDAY($F14,2)+1),"u","") | P14: =IF(P$5=($F14-WEEKDAY($F14,2)+1),"u","") | Q14: =IF(Q$5=($F14-WEEKDAY($F14,2)+1),"u","") | R14: =IF(R$5=($F14-WEEKDAY($F14,2)+1),"u","") | ... FW14: =IF(FW$5=($F14-WEEKDAY($F14,2)+1),"u","")
B15: =Portfolio_Daten!#REF! -> #REF! | C15: =Portfolio_Daten!B13 -> 0 | D15: =Portfolio_Daten!E13 -> 0 | E15: =Portfolio_Daten!T13 -> 0 | F15: =Portfolio_Daten!U13 -> 0 | G15: =IF(F15="","",NETWORKDAYS(E15,F15,Parameter!$C$4:$C$51)) -> 0 | H15: =Portfolio_Daten!AG13 -> 0 | I15: =Portfolio_Daten!AI13 -> 0 | K15: =IF(K$5=($F15-WEEKDAY($F15,2)+1),"u","") | L15: =IF(L$5=($F15-WEEKDAY($F15,2)+1),"u","") | M15: =IF(M$5=($F15-WEEKDAY($F15,2)+1),"u","") | N15: =IF(N$5=($F15-WEEKDAY($F15,2)+1),"u","") | O15: =IF(O$5=($F15-WEEKDAY($F15,2)+1),"u","") | P15: =IF(P$5=($F15-WEEKDAY($F15,2)+1),"u","") | Q15: =IF(Q$5=($F15-WEEKDAY($F15,2)+1),"u","") | R15: =IF(R$5=($F15-WEEKDAY($F15,2)+1),"u","") | ... FW15: =IF(FW$5=($F15-WEEKDAY($F15,2)+1),"u","")
B16: =Portfolio_Daten!#REF! -> #REF! | C16: =Portfolio_Daten!B14 -> 0 | D16: =Portfolio_Daten!E14 -> 0 | E16: =Portfolio_Daten!T14 -> 0 | F16: =Portfolio_Daten!U14 -> 0 | G16: =IF(F16="","",NETWORKDAYS(E16,F16,Parameter!$C$4:$C$51)) -> 0 | H16: =Portfolio_Daten!AG14 -> 0 | I16: =Portfolio_Daten!AI14 -> 0 | K16: =IF(K$5=($F16-WEEKDAY($F16,2)+1),"u","") | L16: =IF(L$5=($F16-WEEKDAY($F16,2)+1),"u","") | M16: =IF(M$5=($F16-WEEKDAY($F16,2)+1),"u","") | N16: =IF(N$5=($F16-WEEKDAY($F16,2)+1),"u","") | O16: =IF(O$5=($F16-WEEKDAY($F16,2)+1),"u","") | P16: =IF(P$5=($F16-WEEKDAY($F16,2)+1),"u","") | Q16: =IF(Q$5=($F16-WEEKDAY($F16,2)+1),"u","") | R16: =IF(R$5=($F16-WEEKDAY($F16,2)+1),"u","") | ... FW16: =IF(FW$5=($F16-WEEKDAY($F16,2)+1),"u","")
B17: =Portfolio_Daten!#REF! -> #REF! | C17: =Portfolio_Daten!B15 -> 0 | D17: =Portfolio_Daten!E15 -> 0 | E17: =Portfolio_Daten!T15 -> 0 | F17: =Portfolio_Daten!U15 -> 0 | G17: =IF(F17="","",NETWORKDAYS(E17,F17,Parameter!$C$4:$C$51)) -> 0 | H17: =Portfolio_Daten!AG15 -> 0 | I17: =Portfolio_Daten!AI15 -> 0 | K17: =IF(K$5=($F17-WEEKDAY($F17,2)+1),"u","") | L17: =IF(L$5=($F17-WEEKDAY($F17,2)+1),"u","") | M17: =IF(M$5=($F17-WEEKDAY($F17,2)+1),"u","") | N17: =IF(N$5=($F17-WEEKDAY($F17,2)+1),"u","") | O17: =IF(O$5=($F17-WEEKDAY($F17,2)+1),"u","") | P17: =IF(P$5=($F17-WEEKDAY($F17,2)+1),"u","") | Q17: =IF(Q$5=($F17-WEEKDAY($F17,2)+1),"u","") | R17: =IF(R$5=($F17-WEEKDAY($F17,2)+1),"u","") | ... FW17: =IF(FW$5=($F17-WEEKDAY($F17,2)+1),"u","")
B18: =Portfolio_Daten!#REF! -> #REF! | C18: =Portfolio_Daten!B16 -> 0 | D18: =Portfolio_Daten!E16 -> 0 | E18: =Portfolio_Daten!T16 -> 0 | F18: =Portfolio_Daten!U16 -> 0 | G18: =IF(F18="","",NETWORKDAYS(E18,F18,Parameter!$C$4:$C$51)) -> 0 | H18: =Portfolio_Daten!AG16 -> 0 | I18: =Portfolio_Daten!AI16 -> 0 | K18: =IF(K$5=($F18-WEEKDAY($F18,2)+1),"u","") | L18: =IF(L$5=($F18-WEEKDAY($F18,2)+1),"u","") | M18: =IF(M$5=($F18-WEEKDAY($F18,2)+1),"u","") | N18: =IF(N$5=($F18-WEEKDAY($F18,2)+1),"u","") | O18: =IF(O$5=($F18-WEEKDAY($F18,2)+1),"u","") | P18: =IF(P$5=($F18-WEEKDAY($F18,2)+1),"u","") | Q18: =IF(Q$5=($F18-WEEKDAY($F18,2)+1),"u","") | R18: =IF(R$5=($F18-WEEKDAY($F18,2)+1),"u","") | ... FW18: =IF(FW$5=($F18-WEEKDAY($F18,2)+1),"u","")
B19: =Portfolio_Daten!#REF! -> #REF! | C19: =Portfolio_Daten!B17 -> 0 | D19: =Portfolio_Daten!E17 -> 0 | E19: =Portfolio_Daten!T17 -> 0 | F19: =Portfolio_Daten!U17 -> 0 | G19: =IF(F19="","",NETWORKDAYS(E19,F19,Parameter!$C$4:$C$51)) -> 0 | H19: =Portfolio_Daten!AG17 -> 0 | I19: =Portfolio_Daten!AI17 -> 0 | K19: =IF(K$5=($F19-WEEKDAY($F19,2)+1),"u","") | L19: =IF(L$5=($F19-WEEKDAY($F19,2)+1),"u","") | M19: =IF(M$5=($F19-WEEKDAY($F19,2)+1),"u","") | N19: =IF(N$5=($F19-WEEKDAY($F19,2)+1),"u","") | O19: =IF(O$5=($F19-WEEKDAY($F19,2)+1),"u","") | P19: =IF(P$5=($F19-WEEKDAY($F19,2)+1),"u","") | Q19: =IF(Q$5=($F19-WEEKDAY($F19,2)+1),"u","") | R19: =IF(R$5=($F19-WEEKDAY($F19,2)+1),"u","") | ... FW19: =IF(FW$5=($F19-WEEKDAY($F19,2)+1),"u","")
B20: =Portfolio_Daten!#REF! -> #REF! | C20: =Portfolio_Daten!B19 -> 0 | D20: =Portfolio_Daten!E19 -> 0 | E20: =Portfolio_Daten!T19 -> 0 | F20: =Portfolio_Daten!U19 -> 0 | G20: =IF(F20="","",NETWORKDAYS(E20,F20,Parameter!$C$4:$C$51)) -> 0 | H20: =Portfolio_Daten!AG19 -> 0 | I20: =Portfolio_Daten!AI19 -> 0 | K20: =IF(K$5=($F20-WEEKDAY($F20,2)+1),"u","") | L20: =IF(L$5=($F20-WEEKDAY($F20,2)+1),"u","") | M20: =IF(M$5=($F20-WEEKDAY($F20,2)+1),"u","") | N20: =IF(N$5=($F20-WEEKDAY($F20,2)+1),"u","") | O20: =IF(O$5=($F20-WEEKDAY($F20,2)+1),"u","") | P20: =IF(P$5=($F20-WEEKDAY($F20,2)+1),"u","") | Q20: =IF(Q$5=($F20-WEEKDAY($F20,2)+1),"u","") | R20: =IF(R$5=($F20-WEEKDAY($F20,2)+1),"u","") | ... FW20: =IF(FW$5=($F20-WEEKDAY($F20,2)+1),"u","")
B21: =Portfolio_Daten!#REF! -> #REF! | C21: =Portfolio_Daten!B20 -> 0 | D21: =Portfolio_Daten!E20 -> 0 | E21: =Portfolio_Daten!T20 -> 0 | F21: =Portfolio_Daten!U20 -> 0 | G21: =IF(F21="","",NETWORKDAYS(E21,F21,Parameter!$C$4:$C$51)) -> 0 | H21: =Portfolio_Daten!AG20 -> 0 | I21: =Portfolio_Daten!AI20 -> 0 | K21: =IF(K$5=($F21-WEEKDAY($F21,2)+1),"u","") | L21: =IF(L$5=($F21-WEEKDAY($F21,2)+1),"u","") | M21: =IF(M$5=($F21-WEEKDAY($F21,2)+1),"u","") | N21: =IF(N$5=($F21-WEEKDAY($F21,2)+1),"u","") | O21: =IF(O$5=($F21-WEEKDAY($F21,2)+1),"u","") | P21: =IF(P$5=($F21-WEEKDAY($F21,2)+1),"u","") | Q21: =IF(Q$5=($F21-WEEKDAY($F21,2)+1),"u","") | R21: =IF(R$5=($F21-WEEKDAY($F21,2)+1),"u","") | ... FW21: =IF(FW$5=($F21-WEEKDAY($F21,2)+1),"u","")
B22: =Portfolio_Daten!#REF! -> #REF! | C22: =Portfolio_Daten!B21 -> 0 | D22: =Portfolio_Daten!E21 -> 0 | E22: =Portfolio_Daten!T21 -> 0 | F22: =Portfolio_Daten!U21 -> 0 | G22: =IF(F22="","",NETWORKDAYS(E22,F22,Parameter!$C$4:$C$51)) -> 0 | H22: =Portfolio_Daten!AG21 -> 0 | I22: =Portfolio_Daten!AI21 -> 0 | K22: =IF(K$5=($F22-WEEKDAY($F22,2)+1),"u","") | L22: =IF(L$5=($F22-WEEKDAY($F22,2)+1),"u","") | M22: =IF(M$5=($F22-WEEKDAY($F22,2)+1),"u","") | N22: =IF(N$5=($F22-WEEKDAY($F22,2)+1),"u","") | O22: =IF(O$5=($F22-WEEKDAY($F22,2)+1),"u","") | P22: =IF(P$5=($F22-WEEKDAY($F22,2)+1),"u","") | Q22: =IF(Q$5=($F22-WEEKDAY($F22,2)+1),"u","") | R22: =IF(R$5=($F22-WEEKDAY($F22,2)+1),"u","") | ... FW22: =IF(FW$5=($F22-WEEKDAY($F22,2)+1),"u","")
B23: =Portfolio_Daten!#REF! -> #REF! | C23: =Portfolio_Daten!B22 -> 0 | D23: =Portfolio_Daten!E22 -> 0 | E23: =Portfolio_Daten!T22 -> 0 | F23: =Portfolio_Daten!U22 -> 0 | G23: =IF(F23="","",NETWORKDAYS(E23,F23,Parameter!$C$4:$C$51)) -> 0 | H23: =Portfolio_Daten!AG22 -> 0 | I23: =Portfolio_Daten!AI22 -> 0 | K23: =IF(K$5=($F23-WEEKDAY($F23,2)+1),"u","") | L23: =IF(L$5=($F23-WEEKDAY($F23,2)+1),"u","") | M23: =IF(M$5=($F23-WEEKDAY($F23,2)+1),"u","") | N23: =IF(N$5=($F23-WEEKDAY($F23,2)+1),"u","") | O23: =IF(O$5=($F23-WEEKDAY($F23,2)+1),"u","") | P23: =IF(P$5=($F23-WEEKDAY($F23,2)+1),"u","") | Q23: =IF(Q$5=($F23-WEEKDAY($F23,2)+1),"u","") | R23: =IF(R$5=($F23-WEEKDAY($F23,2)+1),"u","") | ... FW23: =IF(FW$5=($F23-WEEKDAY($F23,2)+1),"u","")
B24: =Portfolio_Daten!#REF! -> #REF! | C24: =Portfolio_Daten!B23 -> 0 | D24: =Portfolio_Daten!E23 -> 0 | E24: =Portfolio_Daten!T23 -> 0 | F24: =Portfolio_Daten!U23 -> 0 | G24: =IF(F24="","",NETWORKDAYS(E24,F24,Parameter!$C$4:$C$51)) -> 0 | H24: =Portfolio_Daten!AG23 -> 0 | I24: =Portfolio_Daten!AI23 -> 0 | K24: =IF(K$5=($F24-WEEKDAY($F24,2)+1),"u","") | L24: =IF(L$5=($F24-WEEKDAY($F24,2)+1),"u","") | M24: =IF(M$5=($F24-WEEKDAY($F24,2)+1),"u","") | N24: =IF(N$5=($F24-WEEKDAY($F24,2)+1),"u","") | O24: =IF(O$5=($F24-WEEKDAY($F24,2)+1),"u","") | P24: =IF(P$5=($F24-WEEKDAY($F24,2)+1),"u","") | Q24: =IF(Q$5=($F24-WEEKDAY($F24,2)+1),"u","") | R24: =IF(R$5=($F24-WEEKDAY($F24,2)+1),"u","") | ... FW24: =IF(FW$5=($F24-WEEKDAY($F24,2)+1),"u","")
B25: =Portfolio_Daten!#REF! -> #REF! | C25: =Portfolio_Daten!B24 -> 0 | D25: =Portfolio_Daten!E24 -> 0 | E25: =Portfolio_Daten!T24 -> 0 | F25: =Portfolio_Daten!U24 -> 0 | G25: =IF(F25="","",NETWORKDAYS(E25,F25,Parameter!$C$4:$C$51)) -> 0 | H25: =Portfolio_Daten!AG24 -> 0 | I25: =Portfolio_Daten!AI24 -> 0 | K25: =IF(K$5=($F25-WEEKDAY($F25,2)+1),"u","") | L25: =IF(L$5=($F25-WEEKDAY($F25,2)+1),"u","") | M25: =IF(M$5=($F25-WEEKDAY($F25,2)+1),"u","") | N25: =IF(N$5=($F25-WEEKDAY($F25,2)+1),"u","") | O25: =IF(O$5=($F25-WEEKDAY($F25,2)+1),"u","") | P25: =IF(P$5=($F25-WEEKDAY($F25,2)+1),"u","") | Q25: =IF(Q$5=($F25-WEEKDAY($F25,2)+1),"u","") | R25: =IF(R$5=($F25-WEEKDAY($F25,2)+1),"u","") | ... FW25: =IF(FW$5=($F25-WEEKDAY($F25,2)+1),"u","")
B26: =Portfolio_Daten!#REF! -> #REF! | C26: =Portfolio_Daten!B25 -> 0 | D26: =Portfolio_Daten!E25 -> 0 | E26: =Portfolio_Daten!T25 -> 0 | F26: =Portfolio_Daten!U25 -> 0 | G26: =IF(F26="","",NETWORKDAYS(E26,F26,Parameter!$C$4:$C$51)) -> 0 | H26: =Portfolio_Daten!AG25 -> 0 | I26: =Portfolio_Daten!AI25 -> 0 | K26: =IF(K$5=($F26-WEEKDAY($F26,2)+1),"u","") | L26: =IF(L$5=($F26-WEEKDAY($F26,2)+1),"u","") | M26: =IF(M$5=($F26-WEEKDAY($F26,2)+1),"u","") | N26: =IF(N$5=($F26-WEEKDAY($F26,2)+1),"u","") | O26: =IF(O$5=($F26-WEEKDAY($F26,2)+1),"u","") | P26: =IF(P$5=($F26-WEEKDAY($F26,2)+1),"u","") | Q26: =IF(Q$5=($F26-WEEKDAY($F26,2)+1),"u","") | R26: =IF(R$5=($F26-WEEKDAY($F26,2)+1),"u","") | ... FW26: =IF(FW$5=($F26-WEEKDAY($F26,2)+1),"u","")
B27: =Portfolio_Daten!#REF! -> #REF! | C27: =Portfolio_Daten!B26 -> 0 | D27: =Portfolio_Daten!E26 -> 0 | E27: =Portfolio_Daten!T26 -> 0 | F27: =Portfolio_Daten!U26 -> 0 | G27: =IF(F27="","",NETWORKDAYS(E27,F27,Parameter!$C$4:$C$51)) -> 0 | H27: =Portfolio_Daten!AG26 -> 0 | I27: =Portfolio_Daten!AI26 -> 0 | K27: =IF(K$5=($F27-WEEKDAY($F27,2)+1),"u","") | L27: =IF(L$5=($F27-WEEKDAY($F27,2)+1),"u","") | M27: =IF(M$5=($F27-WEEKDAY($F27,2)+1),"u","") | N27: =IF(N$5=($F27-WEEKDAY($F27,2)+1),"u","") | O27: =IF(O$5=($F27-WEEKDAY($F27,2)+1),"u","") | P27: =IF(P$5=($F27-WEEKDAY($F27,2)+1),"u","") | Q27: =IF(Q$5=($F27-WEEKDAY($F27,2)+1),"u","") | R27: =IF(R$5=($F27-WEEKDAY($F27,2)+1),"u","") | ... FW27: =IF(FW$5=($F27-WEEKDAY($F27,2)+1),"u","")
B28: =Portfolio_Daten!#REF! -> #REF! | C28: =Portfolio_Daten!B27 -> 0 | D28: =Portfolio_Daten!E27 -> 0 | E28: =Portfolio_Daten!T27 -> 0 | F28: =Portfolio_Daten!U27 -> 0 | G28: =IF(F28="","",NETWORKDAYS(E28,F28,Parameter!$C$4:$C$51)) -> 0 | H28: =Portfolio_Daten!AG27 -> 0 | I28: =Portfolio_Daten!AI27 -> 0 | K28: =IF(K$5=($F28-WEEKDAY($F28,2)+1),"u","") | L28: =IF(L$5=($F28-WEEKDAY($F28,2)+1),"u","") | M28: =IF(M$5=($F28-WEEKDAY($F28,2)+1),"u","") | N28: =IF(N$5=($F28-WEEKDAY($F28,2)+1),"u","") | O28: =IF(O$5=($F28-WEEKDAY($F28,2)+1),"u","") | P28: =IF(P$5=($F28-WEEKDAY($F28,2)+1),"u","") | Q28: =IF(Q$5=($F28-WEEKDAY($F28,2)+1),"u","") | R28: =IF(R$5=($F28-WEEKDAY($F28,2)+1),"u","") | ... FW28: =IF(FW$5=($F28-WEEKDAY($F28,2)+1),"u","")
B29: =Portfolio_Daten!#REF! -> #REF! | C29: =Portfolio_Daten!B28 -> 0 | D29: =Portfolio_Daten!E28 -> 0 | E29: =Portfolio_Daten!T28 -> 0 | F29: =Portfolio_Daten!U28 -> 0 | G29: =IF(F29="","",NETWORKDAYS(E29,F29,Parameter!$C$4:$C$51)) -> 0 | H29: =Portfolio_Daten!AG28 -> 0 | I29: =Portfolio_Daten!AI28 -> 0 | K29: =IF(K$5=($F29-WEEKDAY($F29,2)+1),"u","") | L29: =IF(L$5=($F29-WEEKDAY($F29,2)+1),"u","") | M29: =IF(M$5=($F29-WEEKDAY($F29,2)+1),"u","") | N29: =IF(N$5=($F29-WEEKDAY($F29,2)+1),"u","") | O29: =IF(O$5=($F29-WEEKDAY($F29,2)+1),"u","") | P29: =IF(P$5=($F29-WEEKDAY($F29,2)+1),"u","") | Q29: =IF(Q$5=($F29-WEEKDAY($F29,2)+1),"u","") | R29: =IF(R$5=($F29-WEEKDAY($F29,2)+1),"u","") | ... FW29: =IF(FW$5=($F29-WEEKDAY($F29,2)+1),"u","")
B30: =Portfolio_Daten!#REF! -> #REF! | C30: =Portfolio_Daten!B29 -> 0 | D30: =Portfolio_Daten!E29 -> 0 | E30: =Portfolio_Daten!T29 -> 0 | F30: =Portfolio_Daten!U29 -> 0 | G30: =IF(F30="","",NETWORKDAYS(E30,F30,Parameter!$C$4:$C$51)) -> 0 | H30: =Portfolio_Daten!AG29 -> 0 | I30: =Portfolio_Daten!AI29 -> 0 | K30: =IF(K$5=($F30-WEEKDAY($F30,2)+1),"u","") | L30: =IF(L$5=($F30-WEEKDAY($F30,2)+1),"u","") | M30: =IF(M$5=($F30-WEEKDAY($F30,2)+1),"u","") | N30: =IF(N$5=($F30-WEEKDAY($F30,2)+1),"u","") | O30: =IF(O$5=($F30-WEEKDAY($F30,2)+1),"u","") | P30: =IF(P$5=($F30-WEEKDAY($F30,2)+1),"u","") | Q30: =IF(Q$5=($F30-WEEKDAY($F30,2)+1),"u","") | R30: =IF(R$5=($F30-WEEKDAY($F30,2)+1),"u","") | ... FW30: =IF(FW$5=($F30-WEEKDAY($F30,2)+1),"u","")
B31: =Portfolio_Daten!#REF! -> #REF! | C31: =Portfolio_Daten!B30 -> 0 | D31: =Portfolio_Daten!E30 -> 0 | E31: =Portfolio_Daten!T30 -> 0 | F31: =Portfolio_Daten!U30 -> 0 | G31: =IF(F31="","",NETWORKDAYS(E31,F31,Parameter!$C$4:$C$51)) -> 0 | H31: =Portfolio_Daten!AG30 -> 0 | I31: =Portfolio_Daten!AI30 -> 0 | K31: =IF(K$5=($F31-WEEKDAY($F31,2)+1),"u","") | L31: =IF(L$5=($F31-WEEKDAY($F31,2)+1),"u","") | M31: =IF(M$5=($F31-WEEKDAY($F31,2)+1),"u","") | N31: =IF(N$5=($F31-WEEKDAY($F31,2)+1),"u","") | O31: =IF(O$5=($F31-WEEKDAY($F31,2)+1),"u","") | P31: =IF(P$5=($F31-WEEKDAY($F31,2)+1),"u","") | Q31: =IF(Q$5=($F31-WEEKDAY($F31,2)+1),"u","") | R31: =IF(R$5=($F31-WEEKDAY($F31,2)+1),"u","") | ... FW31: =IF(FW$5=($F31-WEEKDAY($F31,2)+1),"u","")
... B53: =Portfolio_Daten!#REF! -> #REF! | C53: =Portfolio_Daten!B52 -> 0 | D53: =Portfolio_Daten!E52 -> 0 | E53: =Portfolio_Daten!T52 -> 0 | F53: =Portfolio_Daten!U52 -> 0 | G53: =IF(F53="","",NETWORKDAYS(E53,F53,Parameter!$C$4:$C$51)) -> 0 | H53: =Portfolio_Daten!AG52 -> 0 | I53: =Portfolio_Daten!AI52 -> 0 | K53: =IF(K$5=($F53-WEEKDAY($F53,2)+1),"u","") | L53: =IF(L$5=($F53-WEEKDAY($F53,2)+1),"u","") | M53: =IF(M$5=($F53-WEEKDAY($F53,2)+1),"u","") | N53: =IF(N$5=($F53-WEEKDAY($F53,2)+1),"u","") | O53: =IF(O$5=($F53-WEEKDAY($F53,2)+1),"u","") | P53: =IF(P$5=($F53-WEEKDAY($F53,2)+1),"u","") | Q53: =IF(Q$5=($F53-WEEKDAY($F53,2)+1),"u","") | R53: =IF(R$5=($F53-WEEKDAY($F53,2)+1),"u","") | ... FW53: =IF(FW$5=($F53-WEEKDAY($F53,2)+1),"u","")
B54: =Portfolio_Daten!#REF! -> #REF! | C54: =Portfolio_Daten!B54 -> 0 | D54: =Portfolio_Daten!E54 -> 0 | E54: =Portfolio_Daten!T54 -> 0 | F54: =Portfolio_Daten!U54 -> 0 | G54: =IF(F54="","",NETWORKDAYS(E54,F54,Parameter!$C$4:$C$51)) -> 0 | H54: =Portfolio_Daten!AG54 -> 0 | I54: =Portfolio_Daten!AI54 -> 0 | K54: =IF(K$5=($F54-WEEKDAY($F54,2)+1),"u","") | L54: =IF(L$5=($F54-WEEKDAY($F54,2)+1),"u","") | M54: =IF(M$5=($F54-WEEKDAY($F54,2)+1),"u","") | N54: =IF(N$5=($F54-WEEKDAY($F54,2)+1),"u","") | O54: =IF(O$5=($F54-WEEKDAY($F54,2)+1),"u","") | P54: =IF(P$5=($F54-WEEKDAY($F54,2)+1),"u","") | Q54: =IF(Q$5=($F54-WEEKDAY($F54,2)+1),"u","") | R54: =IF(R$5=($F54-WEEKDAY($F54,2)+1),"u","") | ... FW54: =IF(FW$5=($F54-WEEKDAY($F54,2)+1),"u","")
B55: =Portfolio_Daten!#REF! -> #REF! | C55: =Portfolio_Daten!B56 -> 0 | D55: =Portfolio_Daten!E56 -> 0 | E55: =Portfolio_Daten!T56 -> 0 | F55: =Portfolio_Daten!U56 -> 0 | G55: =IF(F55="","",NETWORKDAYS(E55,F55,Parameter!$C$4:$C$51)) -> 0 | H55: =Portfolio_Daten!AG56 -> 0 | I55: =Portfolio_Daten!AI56 -> 0 | K55: =IF(K$5=($F55-WEEKDAY($F55,2)+1),"u","") | L55: =IF(L$5=($F55-WEEKDAY($F55,2)+1),"u","") | M55: =IF(M$5=($F55-WEEKDAY($F55,2)+1),"u","") | N55: =IF(N$5=($F55-WEEKDAY($F55,2)+1),"u","") | O55: =IF(O$5=($F55-WEEKDAY($F55,2)+1),"u","") | P55: =IF(P$5=($F55-WEEKDAY($F55,2)+1),"u","") | Q55: =IF(Q$5=($F55-WEEKDAY($F55,2)+1),"u","") | R55: =IF(R$5=($F55-WEEKDAY($F55,2)+1),"u","") | ... FW55: =IF(FW$5=($F55-WEEKDAY($F55,2)+1),"u","")
B56: =Portfolio_Daten!#REF! -> #REF! | C56: =Portfolio_Daten!B57 -> 0 | D56: =Portfolio_Daten!E57 -> 0 | E56: =Portfolio_Daten!T57 -> 0 | F56: =Portfolio_Daten!U57 -> 0 | G56: =IF(F56="","",NETWORKDAYS(E56,F56,Parameter!$C$4:$C$51)) -> 0 | H56: =Portfolio_Daten!AG57 -> 0 | I56: =Portfolio_Daten!AI57 -> 0 | K56: =IF(K$5=($F56-WEEKDAY($F56,2)+1),"u","") | L56: =IF(L$5=($F56-WEEKDAY($F56,2)+1),"u","") | M56: =IF(M$5=($F56-WEEKDAY($F56,2)+1),"u","") | N56: =IF(N$5=($F56-WEEKDAY($F56,2)+1),"u","") | O56: =IF(O$5=($F56-WEEKDAY($F56,2)+1),"u","") | P56: =IF(P$5=($F56-WEEKDAY($F56,2)+1),"u","") | Q56: =IF(Q$5=($F56-WEEKDAY($F56,2)+1),"u","") | R56: =IF(R$5=($F56-WEEKDAY($F56,2)+1),"u","") | ... FW56: =IF(FW$5=($F56-WEEKDAY($F56,2)+1),"u","")
B57: =Portfolio_Daten!#REF! -> #REF! | C57: =Portfolio_Daten!B58 -> 0 | D57: =Portfolio_Daten!E58 -> 0 | E57: =Portfolio_Daten!T58 -> 0 | F57: =Portfolio_Daten!U58 -> 0 | G57: =IF(F57="","",NETWORKDAYS(E57,F57,Parameter!$C$4:$C$51)) -> 0 | H57: =Portfolio_Daten!AG58 -> 0 | I57: =Portfolio_Daten!AI58 -> 0 | K57: =IF(K$5=($F57-WEEKDAY($F57,2)+1),"u","") | L57: =IF(L$5=($F57-WEEKDAY($F57,2)+1),"u","") | M57: =IF(M$5=($F57-WEEKDAY($F57,2)+1),"u","") | N57: =IF(N$5=($F57-WEEKDAY($F57,2)+1),"u","") | O57: =IF(O$5=($F57-WEEKDAY($F57,2)+1),"u","") | P57: =IF(P$5=($F57-WEEKDAY($F57,2)+1),"u","") | Q57: =IF(Q$5=($F57-WEEKDAY($F57,2)+1),"u","") | R57: =IF(R$5=($F57-WEEKDAY($F57,2)+1),"u","") | ... FW57: =IF(FW$5=($F57-WEEKDAY($F57,2)+1),"u","")
B58: =Portfolio_Daten!#REF! -> #REF! | C58: =Portfolio_Daten!B59 -> 0 | D58: =Portfolio_Daten!E59 -> 0 | E58: =Portfolio_Daten!T59 -> 0 | F58: =Portfolio_Daten!U59 -> 0 | G58: =IF(F58="","",NETWORKDAYS(E58,F58,Parameter!$C$4:$C$51)) -> 0 | H58: =Portfolio_Daten!AG59 -> 0 | I58: =Portfolio_Daten!AI59 -> 0 | K58: =IF(K$5=($F58-WEEKDAY($F58,2)+1),"u","") | L58: =IF(L$5=($F58-WEEKDAY($F58,2)+1),"u","") | M58: =IF(M$5=($F58-WEEKDAY($F58,2)+1),"u","") | N58: =IF(N$5=($F58-WEEKDAY($F58,2)+1),"u","") | O58: =IF(O$5=($F58-WEEKDAY($F58,2)+1),"u","") | P58: =IF(P$5=($F58-WEEKDAY($F58,2)+1),"u","") | Q58: =IF(Q$5=($F58-WEEKDAY($F58,2)+1),"u","") | R58: =IF(R$5=($F58-WEEKDAY($F58,2)+1),"u","") | ... FW58: =IF(FW$5=($F58-WEEKDAY($F58,2)+1),"u","")
B59: =Portfolio_Daten!#REF! -> #REF! | C59: =Portfolio_Daten!B60 -> 0 | D59: =Portfolio_Daten!E60 -> 0 | E59: =Portfolio_Daten!T60 -> 0 | F59: =Portfolio_Daten!U60 -> 0 | G59: =IF(F59="","",NETWORKDAYS(E59,F59,Parameter!$C$4:$C$51)) -> 0 | H59: =Portfolio_Daten!AG60 -> 0 | I59: =Portfolio_Daten!AI60 -> 0 | K59: =IF(K$5=($F59-WEEKDAY($F59,2)+1),"u","") | L59: =IF(L$5=($F59-WEEKDAY($F59,2)+1),"u","") | M59: =IF(M$5=($F59-WEEKDAY($F59,2)+1),"u","") | N59: =IF(N$5=($F59-WEEKDAY($F59,2)+1),"u","") | O59: =IF(O$5=($F59-WEEKDAY($F59,2)+1),"u","") | P59: =IF(P$5=($F59-WEEKDAY($F59,2)+1),"u","") | Q59: =IF(Q$5=($F59-WEEKDAY($F59,2)+1),"u","") | R59: =IF(R$5=($F59-WEEKDAY($F59,2)+1),"u","") | ... FW59: =IF(FW$5=($F59-WEEKDAY($F59,2)+1),"u","")
B60: =Portfolio_Daten!#REF! -> #REF! | C60: =Portfolio_Daten!B61 -> 0 | D60: =Portfolio_Daten!E61 -> 0 | E60: =Portfolio_Daten!T61 -> 0 | F60: =Portfolio_Daten!U61 -> 0 | G60: =IF(F60="","",NETWORKDAYS(E60,F60,Parameter!$C$4:$C$51)) -> 0 | H60: =Portfolio_Daten!AG61 -> 0 | I60: =Portfolio_Daten!AI61 -> 0 | K60: =IF(K$5=($F60-WEEKDAY($F60,2)+1),"u","") | L60: =IF(L$5=($F60-WEEKDAY($F60,2)+1),"u","") | M60: =IF(M$5=($F60-WEEKDAY($F60,2)+1),"u","") | N60: =IF(N$5=($F60-WEEKDAY($F60,2)+1),"u","") | O60: =IF(O$5=($F60-WEEKDAY($F60,2)+1),"u","") | P60: =IF(P$5=($F60-WEEKDAY($F60,2)+1),"u","") | Q60: =IF(Q$5=($F60-WEEKDAY($F60,2)+1),"u","") | R60: =IF(R$5=($F60-WEEKDAY($F60,2)+1),"u","") | ... FW60: =IF(FW$5=($F60-WEEKDAY($F60,2)+1),"u","")
B61: =Portfolio_Daten!#REF! -> #REF! | C61: =Portfolio_Daten!B62 -> 0 | D61: =Portfolio_Daten!E62 -> 0 | E61: =Portfolio_Daten!T62 -> 0 | F61: =Portfolio_Daten!U62 -> 0 | G61: =IF(F61="","",NETWORKDAYS(E61,F61,Parameter!$C$4:$C$51)) -> 0 | H61: =Portfolio_Daten!AG62 -> 0 | I61: =Portfolio_Daten!AI62 -> 0 | K61: =IF(K$5=($F61-WEEKDAY($F61,2)+1),"u","") | L61: =IF(L$5=($F61-WEEKDAY($F61,2)+1),"u","") | M61: =IF(M$5=($F61-WEEKDAY($F61,2)+1),"u","") | N61: =IF(N$5=($F61-WEEKDAY($F61,2)+1),"u","") | O61: =IF(O$5=($F61-WEEKDAY($F61,2)+1),"u","") | P61: =IF(P$5=($F61-WEEKDAY($F61,2)+1),"u","") | Q61: =IF(Q$5=($F61-WEEKDAY($F61,2)+1),"u","") | R61: =IF(R$5=($F61-WEEKDAY($F61,2)+1),"u","") | ... FW61: =IF(FW$5=($F61-WEEKDAY($F61,2)+1),"u","")
B62: =Portfolio_Daten!#REF! -> #REF! | C62: =Portfolio_Daten!B63 -> 0 | D62: =Portfolio_Daten!E63 -> 0 | E62: =Portfolio_Daten!T63 -> 0 | F62: =Portfolio_Daten!U63 -> 0 | G62: =IF(F62="","",NETWORKDAYS(E62,F62,Parameter!$C$4:$C$51)) -> 0 | H62: =Portfolio_Daten!AG63 -> 0 | I62: =Portfolio_Daten!AI63 -> 0 | K62: =IF(K$5=($F62-WEEKDAY($F62,2)+1),"u","") | L62: =IF(L$5=($F62-WEEKDAY($F62,2)+1),"u","") | M62: =IF(M$5=($F62-WEEKDAY($F62,2)+1),"u","") | N62: =IF(N$5=($F62-WEEKDAY($F62,2)+1),"u","") | O62: =IF(O$5=($F62-WEEKDAY($F62,2)+1),"u","") | P62: =IF(P$5=($F62-WEEKDAY($F62,2)+1),"u","") | Q62: =IF(Q$5=($F62-WEEKDAY($F62,2)+1),"u","") | R62: =IF(R$5=($F62-WEEKDAY($F62,2)+1),"u","") | ... FW62: =IF(FW$5=($F62-WEEKDAY($F62,2)+1),"u","")
...

Sheet Dashboard_LVÜbersicht
B1: Vorhaben der Leistungsvereinbarung - Gesamtübersicht | T1: Berichtsdatum: | U1: =Arbeitsbereich!M1 -> 46099

Sheet DB_Budgeteinbehalt
B1: Vorhaben der Leistungsvereinbarung mit Budgeteinbehalt | T1: Berichtsdatum: | U1: =Arbeitsbereich!M1 -> 46099

Sheet DB_LeistungsbereicheLV
B1: Vorhaben der Leistungsvereinbarung nach Leistungsbereichen | U1: Berichtsdatum: | V1: =Arbeitsbereich!M1 -> 46099

Sheet Dashboard_PAG
C1: Vorhaben der Leistungsvereinbarung nach Projektauftraggeber:in | AA1: Berichtsdatum: | AB1: =Arbeitsbereich!M1 -> 46099

Sheet Pipeline_Arbeitsbereich_alt
B1: Projektportfolio Pipeline | H1: Berichtsdatum: | I1: =Arbeitsbereich!M1 -> 46099
C3: Aktuelles Datum: | D3: =TODAY() -> 46091 | G3: LV-Periode: | H3: =Portfolio_Daten!L3 -> 0
B4: # | C4: Projekt | D4: Projektart | E4: Projektart für Pipeline | F4: Projektart mit Versatz | G4: Projektphase | H4: Projektphase für Pipeline | I4: Projektphase mit Versatz | J4: Fortschritt (%)
B5: =Portfolio_Daten!#REF! -> #REF! | C5: =Portfolio_Daten!E5 -> Zentrale Beschaffung Labormaterialien | D5: =#REF! -> #REF! | E5: =VLOOKUP(D5,Parameter!#REF!,2,FALSE) -> #REF! | F5: =Tabelle145[[#This Row],[Projektart für Pipeline]]+RAND()*0.9-0.1 -> #REF! | G5: =Portfolio_Daten!AG5 -> In Arbeit | H5: =VLOOKUP(G5,Parameter!$P$4:$Q$9,2,FALSE) -> 3 | I5: =Tabelle145[[#This Row],[Projektphase für Pipeline]]+RAND()*0.9-0.1 -> 3.6985502 | J5: =Portfolio_Daten!AI5 -> 0.33
B6: =Portfolio_Daten!#REF! -> #REF! | C6: =Portfolio_Daten!E6 -> Digitale Lehr- und Prüfungsorganisation | D6: =#REF! -> #REF! | E6: =VLOOKUP(D6,Parameter!#REF!,2,FALSE) -> #REF! | F6: =Tabelle145[[#This Row],[Projektart für Pipeline]]+RAND()*0.9-0.1 -> #REF! | G6: =Portfolio_Daten!AG6 -> Planung | H6: =VLOOKUP(G6,Parameter!$P$4:$Q$9,2,FALSE) -> 2 | I6: =Tabelle145[[#This Row],[Projektphase für Pipeline]]+RAND()*0.9-0.1 -> 2.0121115 | J6: =Portfolio_Daten!AI6 -> 0
B7: =Portfolio_Daten!#REF! -> #REF! | C7: =Portfolio_Daten!E7 -> Einführung Erweiterungsstudium Meereskrabben | D7: =#REF! -> #REF! | E7: =VLOOKUP(D7,Parameter!#REF!,2,FALSE) -> #REF! | F7: =Tabelle145[[#This Row],[Projektart für Pipeline]]+RAND()*0.9-0.1 -> #REF! | G7: =Portfolio_Daten!AG7 -> Idee erfasst/noch nicht gestartet | H7: =VLOOKUP(G7,Parameter!$P$4:$Q$9,2,FALSE) -> 1 | I7: =Tabelle145[[#This Row],[Projektphase für Pipeline]]+RAND()*0.9-0.1 -> 1.7450981 | J7: =Portfolio_Daten!AI7 -> 0
B8: =Portfolio_Daten!#REF! -> #REF! | C8: =Portfolio_Daten!E8 -> Neubau „Elefantenhaus“ – Trainings- und Untersuchungszentrum für Großsäuger | D8: =#REF! -> #REF! | E8: =VLOOKUP(D8,Parameter!#REF!,2,FALSE) -> #REF! | F8: =Tabelle145[[#This Row],[Projektart für Pipeline]]+RAND()*0.9-0.1 -> #REF! | G8: =Portfolio_Daten!AG8 -> Planung | H8: =VLOOKUP(G8,Parameter!$P$4:$Q$9,2,FALSE) -> 2 | I8: =Tabelle145[[#This Row],[Projektphase für Pipeline]]+RAND()*0.9-0.1 -> 2.3328894 | J8: =Portfolio_Daten!AI8 -> 0.1
